2022-03-29 09:52:46,558 INFO    MainThread:293099 [wandb_setup.py:_flush():69] setting env: {}
2022-03-29 09:52:46,558 INFO    MainThread:293099 [wandb_setup.py:_flush():69] setting login settings: {}
2022-03-29 09:52:46,558 INFO    MainThread:293099 [wandb_init.py:_log_setup():338] Logging user logs to /lila/home/harrigan/damuta/docs/examples/wandb/run-20220329_095246-lmo1f6yi/logs/debug.log
2022-03-29 09:52:46,559 INFO    MainThread:293099 [wandb_init.py:_log_setup():339] Logging internal logs to /lila/home/harrigan/damuta/docs/examples/wandb/run-20220329_095246-lmo1f6yi/logs/debug-internal.log
2022-03-29 09:52:46,559 INFO    MainThread:293099 [wandb_init.py:init():371] calling init triggers
2022-03-29 09:52:46,559 INFO    MainThread:293099 [wandb_init.py:init():376] wandb.init called with sweep_config: {}
config: {}
2022-03-29 09:52:46,559 INFO    MainThread:293099 [wandb_init.py:init():391] re-initializing run, found existing run on stack: 1fvca2u6
2022-03-29 09:52:46,561 INFO    MainThread:293099 [wandb_run.py:finish():1295] finishing run harrig12/damuta-docs_examples/1fvca2u6
2022-03-29 09:52:46,563 INFO    MainThread:293099 [jupyter.py:save_history():339] not saving jupyter history
2022-03-29 09:52:46,563 INFO    MainThread:293099 [jupyter.py:save_ipynb():284] not saving jupyter notebook
2022-03-29 09:52:46,563 INFO    MainThread:293099 [wandb_init.py:_jupyter_teardown():270] cleaning up jupyter logic
2022-03-29 09:52:46,563 INFO    MainThread:293099 [wandb_run.py:_atexit_cleanup():1595] got exitcode: 0
2022-03-29 09:52:46,563 INFO    MainThread:293099 [wandb_run.py:_restore():1567] restore
2022-03-29 09:52:46,652 INFO    MainThread:293099 [wandb_run.py:_restore():1567] restore
2022-03-29 09:52:46,690 ERROR   MainThread:293099 [wandb_init.py:init():788] error
Traceback (most recent call last):
  File "/home/harrigan/miniconda3/envs/pymc3/lib/python3.8/site-packages/wandb/sdk/wandb_run.py", line 1603, in _atexit_cleanup
    self._on_finish()
  File "/home/harrigan/miniconda3/envs/pymc3/lib/python3.8/site-packages/wandb/sdk/wandb_run.py", line 1760, in _on_finish
    self._backend.interface.publish_telemetry(self._telemetry_obj)
  File "/home/harrigan/miniconda3/envs/pymc3/lib/python3.8/site-packages/wandb/sdk/interface/interface.py", line 233, in publish_telemetry
    self._publish(rec)
  File "/home/harrigan/miniconda3/envs/pymc3/lib/python3.8/site-packages/wandb/sdk/interface/interface.py", line 535, in _publish
    raise Exception("The wandb backend process has shutdown")
Exception: The wandb backend process has shutdown

During handling of the above exception, another exception occurred:

Traceback (most recent call last):
  File "/home/harrigan/miniconda3/envs/pymc3/lib/python3.8/site-packages/wandb/sdk/wandb_init.py", line 762, in init
    run = wi.init()
  File "/home/harrigan/miniconda3/envs/pymc3/lib/python3.8/site-packages/wandb/sdk/wandb_init.py", line 408, in init
    self._wl._global_run_stack[-1].finish()
  File "/home/harrigan/miniconda3/envs/pymc3/lib/python3.8/site-packages/wandb/sdk/wandb_run.py", line 1299, in finish
    self._atexit_cleanup(exit_code=exit_code)
  File "/home/harrigan/miniconda3/envs/pymc3/lib/python3.8/site-packages/wandb/sdk/wandb_run.py", line 1612, in _atexit_cleanup
    self._backend.cleanup()
  File "/home/harrigan/miniconda3/envs/pymc3/lib/python3.8/site-packages/wandb/sdk/backend/backend.py", line 167, in cleanup
    self.interface.join()
  File "/home/harrigan/miniconda3/envs/pymc3/lib/python3.8/site-packages/wandb/sdk/interface/interface.py", line 835, in join
    _ = self._communicate(record)
  File "/home/harrigan/miniconda3/envs/pymc3/lib/python3.8/site-packages/wandb/sdk/interface/interface.py", line 544, in _communicate
    return self._communicate_async(rec, local=local).get(timeout=timeout)
  File "/home/harrigan/miniconda3/envs/pymc3/lib/python3.8/site-packages/wandb/sdk/interface/interface.py", line 549, in _communicate_async
    raise Exception("The wandb backend process has shutdown")
Exception: The wandb backend process has shutdown
